/work/sheidaei/conda/envs/mytorch/lib/python3.9/site-packages/torch/functional.py:504: UserWarning: torch.meshgrid: in an upcoming release, it will be required to pass the indexing argument. (Triggered internally at /opt/conda/conda-bld/pytorch_1666643016022/work/aten/src/ATen/native/TensorShape.cpp:3190.)
  return _VF.meshgrid(tensors, **kwargs)  # type: ignore[attr-defined]
Namespace(root_path='/work/sheidaei/mhashemi/data/mat', dataset='Design', list_dir='./lists/lists_Design', num_classes=2, max_iterations=288, max_epochs=100, batch_size=24, gpu=4, world_size=-1, rank=-1, dist_url='env://', dist_backend='nccl', local_rank=-1, deterministic=1, base_lr=0.01, img_size=[160, 160, 160], seed=1234, n_skip=4, vit_name='Conv-ViT-Gen-B_16', vit_patches_size=[8, 8, 8], is_pretrain=True, exp='TV_Design[160, 160, 160]', distributed=False)
13 iterations per epoch. 1300 max iterations 
  0%|                                         | 0/100 [00:00<?, ?it/s]  0%|                                         | 0/100 [00:00<?, ?it/s]
Traceback (most recent call last):
  File "/home/mhashemi/TransVNet/train_deg.py", line 174, in <module>
    trainer[dataset_name](args, model, snapshot_path)
  File "/home/mhashemi/TransVNet/trainer.py", line 256, in trainer_mat
    for i_batch, sampled_batch in enumerate(trainloader):
  File "/work/sheidaei/conda/envs/mytorch/lib/python3.9/site-packages/torch/utils/data/dataloader.py", line 628, in __next__
    data = self._next_data()
  File "/work/sheidaei/conda/envs/mytorch/lib/python3.9/site-packages/torch/utils/data/dataloader.py", line 1333, in _next_data
    return self._process_data(data)
  File "/work/sheidaei/conda/envs/mytorch/lib/python3.9/site-packages/torch/utils/data/dataloader.py", line 1359, in _process_data
    data.reraise()
  File "/work/sheidaei/conda/envs/mytorch/lib/python3.9/site-packages/torch/_utils.py", line 543, in reraise
    raise exception
FileNotFoundError: Caught FileNotFoundError in DataLoader worker process 0.
Original Traceback (most recent call last):
  File "/work/sheidaei/conda/envs/mytorch/lib/python3.9/site-packages/torch/utils/data/_utils/worker.py", line 302, in _worker_loop
    data = fetcher.fetch(index)
  File "/work/sheidaei/conda/envs/mytorch/lib/python3.9/site-packages/torch/utils/data/_utils/fetch.py", line 58, in fetch
    data = [self.dataset[idx] for idx in possibly_batched_index]
  File "/work/sheidaei/conda/envs/mytorch/lib/python3.9/site-packages/torch/utils/data/_utils/fetch.py", line 58, in <listcomp>
    data = [self.dataset[idx] for idx in possibly_batched_index]
  File "/home/mhashemi/TransVNet/datasets/dataset_deg.py", line 189, in __getitem__
    image = h5py.File(file_path, 'r').get('phase_IND_original')
  File "/work/sheidaei/conda/envs/mytorch/lib/python3.9/site-packages/h5py/_hl/files.py", line 533, in __init__
    fid = make_fid(name, mode, userblock_size, fapl, fcpl, swmr=swmr)
  File "/work/sheidaei/conda/envs/mytorch/lib/python3.9/site-packages/h5py/_hl/files.py", line 226, in make_fid
    fid = h5f.open(name, flags, fapl=fapl)
  File "h5py/_objects.pyx", line 54, in h5py._objects.with_phil.wrapper
  File "h5py/_objects.pyx", line 55, in h5py._objects.with_phil.wrapper
  File "h5py/h5f.pyx", line 106, in h5py.h5f.open
FileNotFoundError: [Errno 2] Unable to open file (unable to open file: name = '/work/sheidaei/mhashemi/data/mat/220153.mat', errno = 2, error message = 'No such file or directory', flags = 0, o_flags = 0)

